Workbook

Sheet README
A1: Solar Cell Design & Optimization Tool v4.0 rev B — Complete Data Book
A2: Every parameter, benchmark and result with citation, DOI and verification status. Generated from the repository's machine-readable registries and live engines.
A4: Sheet index
A5: Sheet | B5: Contents
A6: Reference_Registry | B6: All 37 model/benchmark references + material-database references; DOI, usage, confidence tier, verification status
A7: Physical_Constants | B7: CODATA constants and model constants (Richter coefficients, ni_eff) with sources
A8: Materials_Perovskite | B8: Perovskite/CdTe absorbers, ETLs, HTLs — full parameter sets with per-material references
A9: Silicon_Presets | B9: Five c-Si architectures: parameters, certified targets, live model results, error formulas, DOIs
A10: Organic_Presets | B10: Six BHJ blends: parameters, certified targets, live model results, error formulas, DOIs
A11: Tandem_Grades | B11: 2020/2023/2025 perovskite-Si grades: parameters, certified lineage, model results, errors
A12: Benchmarks_Experimental | B12: The 14-device certified suite (validation_multi_tech.json) with formula-computed errors and PASS flags
A13: CrossTool_Checks | B13: The 9-check SCAPS-1D / Lumerical-class / redundancy suite (validation_cross_tool.json)
A14: SCAPS_Suite | B14: 10 published-SCAPS replication devices (Voc/Jsc/FF/PCE, ours vs published, DOI per device)
A15: Tutorial_Assertions | B15: 22 hand-solved mathematical examples asserted against the live engines
A16: TMM_nk_Data | B16: Complex refractive-index tables used by the transfer-matrix optical solver, with sources
A17: JV_Curves | B17: Live simulated J-V data for all four technologies + chart
A19: Live summary (formulas)
A20: Experimental benchmarks passing | B20: =COUNTIF(Benchmarks_Experimental!J:J,"PASS")&" / "&COUNT(Benchmarks_Experimental!D:D) -> 15 / 14
A21: Mean |PCE error| (experimental) | B21: =AVERAGE(Benchmarks_Experimental!H5:H18) -> 0.0076051417
A22: Max |PCE error| (experimental) | B22: =MAX(Benchmarks_Experimental!H5:H18) -> 0.019085619
A23: Cross-tool checks passing | B23: =COUNTIF(CrossTool_Checks!E:E,"PASS")&" / 9" -> 10 / 9
A24: Tutorial assertions passing | B24: =COUNTIF(Tutorial_Assertions!D:D,"PASS")&" / 22" -> 23 / 22
A25: SCAPS-suite mean |PCE error| | B25: =AVERAGE(SCAPS_Suite!L5:L14) -> 0.006725496
A26: References verified (registry) | B26: =COUNTIF(Reference_Registry!G:G,"YES")&" / "&COUNTA(Reference_Registry!A5:A200) -> 67 / 85
A28: Legend
A29: Blue text = hardcoded model/preset inputs (sourced; see reference column).
A30: Black = formulas computed in-sheet (errors, pass flags, sums) — the workbook recalculates if you edit inputs.
A31: Every DOI column has a clickable resolver link; 'Verified' = citation cross-checked against the Consensus academic index in an audited build.
A32: Reproduce any results sheet: run the named script in scripts/ — this workbook was generated from those artifacts and the live engines.

Sheet Reference_Registry
A1: Reference Registry — every citation in the tool
A2: Sources: data/multi_technology_database.json (v4 registry) + data/materials_database.json (_references). 'Verified' = cross-checked against the Consensus academic index (audited builds incl. this data-book build: Green 2008 and Koster 2005 verified today).
A4: Key | B4: Citation | C4: DOI | D4: Resolver | E4: Used for | F4: Confidence | G4: Verified | H4: Registry
A5: richter_2012_prb | B5: A. Richter, S. W. Glunz, F. Werner, J. Schmidt, A. Cuevas, 'Improved quantitative description of Auger recombination in crystalline silicon', Phys. Rev. B 86, 165202 (2012) | C5: 10.1103/PhysRevB.86.165202 | D5: =HYPERLINK("https://doi.org/"&C5,"open") -> open | E5: Intrinsic Auger + radiative recombination parameterization in physics/silicon.py | F5: HIGH | G5: YES | H5: multi-technology v4
A6: niewelt_2022_solmat | B6: T. Niewelt et al., 'Reassessment of the intrinsic bulk recombination in crystalline silicon', Sol. Energy Mater. Sol. Cells 235, 111467 (2022) | C6: 10.1016/j.solmat.2021.111467 | D6: =HYPERLINK("https://doi.org/"&C6,"open") -> open | E6: Alternative intrinsic recombination model (auger_model='niewelt2022'); 29.4% c-Si single-junction limit | F6: HIGH | G6: YES | H6: multi-technology v4
A7: kerr_2002_jap | B7: M. J. Kerr, A. Cuevas, 'General parameterization of Auger recombination in crystalline silicon', J. Appl. Phys. 91, 2473 (2002) | C7: 10.1063/1.1432476 | D7: =HYPERLINK("https://doi.org/"&C7,"open") -> open | E7: Implied-Voc / lifetime methodology; historical Auger parameterization | F7: HIGH | G7: YES | H7: multi-technology v4
A8: green_2008_solmat | B8: M. A. Green, 'Self-consistent optical parameters of intrinsic silicon at 300 K including temperature coefficients', Sol. Energy Mater. Sol. Cells 92, 1305 (2008) | C8: 10.1016/j.solmat.2008.06.009 | D8: =HYPERLINK("https://doi.org/"&C8,"open") -> open | E8: c-Si absorption coefficient table alpha(lambda) in physics/silicon.py | F8: HIGH | G8: YES | H8: multi-technology v4
A9: tiedje_1984_ted | B9: T. Tiedje, E. Yablonovitch, G. D. Cody, B. G. Brooks, 'Limiting efficiency of silicon solar cells', IEEE Trans. Electron Devices 31, 711 (1984) | C9: 10.1109/T-ED.1984.21594 | D9: =HYPERLINK("https://doi.org/"&C9,"open") -> open | E9: Lambertian light-trapping absorptance A = alpha/(alpha + 1/(4 n^2 W)) | F9: MEDIUM | G9: — | H9: multi-technology v4
A10: altermatt_2003_jap | B10: P. P. Altermatt, A. Schenk, F. Geelhaar, G. Heiser, 'Reassessment of the intrinsic carrier density in crystalline silicon in view of band-gap narrowing', J. Appl. Phys. 93, 1598 (2003) | C10: 10.1063/1.1529297 | D10: =HYPERLINK("https://doi.org/"&C10,"open") -> open | E10: ni_eff = 9.65e9 cm^-3 at 300 K | F10: MEDIUM | G10: — | H10: multi-technology v4
A11: green_1981_sse | B11: M. A. Green, 'Solar cell fill factors: General graph and empirical expressions', Solid-State Electron. 24, 788 (1981) | C11: 10.1016/0038-1101(81)90062-9 | D11: =HYPERLINK("https://doi.org/"&C11,"open") -> open | E11: Empirical FF0(voc) expression | F11: MEDIUM | G11: — | H11: multi-technology v4
A12: yoshikawa_2017_natenergy | B12: K. Yoshikawa et al., 'Silicon heterojunction solar cell with interdigitated back contacts for a photoconversion efficiency over 26%', Nat. Energy 2, 17032 (2017) | C12: 10.1038/nenergy.2017.32 | D12: =HYPERLINK("https://doi.org/"&C12,"open") -> open | E12: SHJ-IBC preset benchmark (26.3%; improved to 26.6-26.7% in the companion paper) | F12: HIGH | G12: YES | H12: multi-technology v4
A13: yoshikawa_2017_solmat | B13: K. Yoshikawa et al., 'Exceeding conversion efficiency of 26% by heterojunction interdigitated back contact solar cell with thin film Si technology', Sol. Energy Mater. Sol. Cells 173, 37 (2017) | C13: 10.1016/j.solmat.2017.06.024 | D13: =HYPERLINK("https://doi.org/"&C13,"open") -> open | E13: 26.6% certified SHJ-IBC device (Fraunhofer ISE CalLab) | F13: HIGH | G13: YES | H13: multi-technology v4
A14: lin_2023_natenergy | B14: H. Lin et al., 'Silicon heterojunction solar cells with up to 26.81% efficiency achieved by electrically optimized nanocrystalline-silicon hole contact layers', Nat. Energy 8, 789 (2023) | C14: 10.1038/s41560-023-01255-2 | D14: =HYPERLINK("https://doi.org/"&C14,"open") -> open | E14: SHJ both-side preset benchmark (26.81%, Voc 751.4 mV, FF up to 86.59%) | F14: HIGH | G14: YES | H14: multi-technology v4
A15: richter_2021_natenergy | B15: A. Richter et al., 'Design rules for high-efficiency both-sides-contacted silicon solar cells with balanced charge carrier transport and recombination losses', Nat. Energy 6, 429 (2021) | C15: 10.1038/s41560-021-00805-w | D15: =HYPERLINK("https://doi.org/"&C15,"open") -> open | E15: TOPCon back-junction preset benchmark (26.0%) | F15: HIGH | G15: YES | H15: multi-technology v4
A16: wang_2024_natcomm | B16: G. Wang et al., '27.09%-efficiency silicon heterojunction back contact solar cell and going beyond', Nat. Commun. 15 (2024) | C16: 10.1038/s41467-024-47455-6 | D16: =HYPERLINK("https://doi.org/"&C16,"open") -> open | E16: Context: current certified HBC frontier for c-Si | F16: MEDIUM | G16: — | H16: multi-technology v4
... A48: jain_2004_solmat | B48: Jain, A. & Kapoor, A., Exact analytical solutions of the parameters of real solar cells using Lambert W-function, Solar Energy Materials and Solar Cells 81, 269-277 (2004) | C48: 10.1016/j.solmat.2003.11.018 | D48: =HYPERLINK("https://doi.org/"&C48,"open") -> open | E48: Exact Lambert-W closed form of the single-diode J-V model used by the measurement-fitting workflow (utils/measurement_fit.py) | F48: HIGH | G48: — | H48: multi-technology v4
A49: stranks_2013 | B49: Stranks et al., Science 342, 341 (2013) | C49: 10.1126/science.1243982 | D49: =HYPERLINK("https://doi.org/"&C49,"open") -> open | F49: HIGH | G49: YES | H49: materials DB v2/v3
A50: chung_2012_jacs_cssni3 | B50: Chung, Song, Im, Androulakis, Malliakas, Li, Freeman, Kenney, Kanatzidis, J. Am. Chem. Soc. 134, 8579-8587 (2012). CsSnI3: Semiconductor or Metal? Hall measurements gave hole mobility ~58 cm^2/Vs, carrier density ~10^17 cm^-3. | C50: 10.1021/ja301539s | D50: =HYPERLINK("https://doi.org/"&C50,"open") -> open | F50: HIGH | G50: YES | H50: materials DB v2/v3
A51: euvrard_2021_nrm | B51: Euvrard, Yan, Mitzi, Nature Reviews Materials (2021). Electrical doping in halide perovskites. Reports MAPbI3 and MAPbBr3 typical doping <10^14 cm^-3 from multiple measurement methods. | C51: 10.1038/s41578-021-00388-8 | D51: =HYPERLINK("https://doi.org/"&C51,"open") -> open | F51: HIGH | G51: YES | H51: materials DB v2/v3
A52: saidaminov_2015_natcomm_mapbbr3 | B52: Saidaminov et al., Nat. Commun. 6, 7586 (2015). High-quality bulk hybrid perovskite single crystals within minutes by inverse temperature crystallization. Reports MAPbBr3 single-crystal trap density 5.8e9 cm^-3 by SCLC. | C52: 10.1038/ncomms8586 | D52: =HYPERLINK("https://doi.org/"&C52,"open") -> open | F52: HIGH | G52: YES | H52: materials DB v2/v3
A53: magomedov_2018_aem_sam | B53: Magomedov, Al-Ashouri, Kasparavicius, Strazdaite, Niaura, Jost, Malinauskas, Albrecht, Getautis, Adv. Energy Mater. 8, 1801892 (2018). Self-assembled hole-transporting monolayer; PCE 17.8%. SAM thickness ~1 nm — bulk transport parameters are not well-defined. | C53: 10.1002/aenm.201801892 | D53: =HYPERLINK("https://doi.org/"&C53,"open") -> open | F53: HIGH | G53: YES | H53: materials DB v2/v3
A54: shin_2016_chemmater_cbts | B54: Shin, Saparov, Zhu, Huhn, Blum, Mitzi, Chem. Mater. 28, 4771-4780 (2016). BaCu2Sn(S,Se)4: Earth-Abundant Chalcogenides for Thin-Film Photovoltaics. | C54: 10.1021/acs.chemmater.6b01832 | D54: =HYPERLINK("https://doi.org/"&C54,"open") -> open | F54: HIGH | G54: YES | H54: materials DB v2/v3
A55: yoo_2021_nature | B55: J. J. Yoo et al., 'Efficient perovskite solar cells via improved carrier management,' Nature 590, 587 (2021) | C55: 10.1038/s41586-021-03285-w | D55: =HYPERLINK("https://doi.org/"&C55,"open") -> open | F55: HIGH | G55: YES | H55: materials DB v2/v3
A56: min_2021_nature | B56: Min, Lee, Kim, Park, Hu, Lee, Kim, Choi, Kim, Cho, Kim, Choi, Hong, Park, Heo, Hwang, Choi, Bae, Kim, Hong, Seo, Park, Kim, Yang, Seok, Nature 598, 444-450 (2021). Perovskite solar cells with atomically coherent interlayers on SnO2 electrodes. NREL-certified PCE 25.7%. | C56: 10.1038/s41586-021-03964-8 | D56: =HYPERLINK("https://doi.org/"&C56,"open") -> open | F56: HIGH | G56: YES | H56: materials DB v2/v3
A57: haider_2018_jappa_cusbs2 | B57: Haider, Anwar, Wang, J. Phys. Chem. Solids (2018). CuSbS2 thin film for solar cell applications. Standard parameter set widely used in SCAPS literature. | C57: 10.1016/j.jpcs.2018.01.024 | D57: =HYPERLINK("https://doi.org/"&C57,"open") -> open | F57: MEDIUM | G57: YES | H57: materials DB v2/v3
A58: amu_2020_jpscond_v2o5 | B58: Amu, Khatibi, Soucase, Mater. Sci. Semicond. Process. (2020). V2O5 as hole transport layer in perovskite solar cells. Standard SCAPS parameter set. | C58: 10.1016/j.mssp.2020.105184 | D58: =HYPERLINK("https://doi.org/"&C58,"open") -> open | F58: MEDIUM | G58: YES | H58: materials DB v2/v3
A59: hadi_2020_solrl_in2s3 | B59: Hadi, Ali, Sarker, Sol. RRL (2020). In2S3 as buffer layer for perovskite solar cells. | C59: 10.1002/solr.202000370 | D59: =HYPERLINK("https://doi.org/"&C59,"open") -> open | F59: MEDIUM | G59: YES | H59: materials DB v2/v3
A60: shi_2015 | B60: Shi et al., Science 347, 519 (2015) | C60: 10.1126/science.aaa2725 | D60: =HYPERLINK("https://doi.org/"&C60,"open") -> open | F60: HIGH | G60: YES | H60: materials DB v2/v3
... A85: savva_2019_solrrl_PEDOT | B85: A. Savva et al., 'PEDOT:PSS in perovskite solar cells,' Solar RRL 3, 1900033 (2019) | C85: 10.1002/solr.201900033 | D85: =HYPERLINK("https://doi.org/"&C85,"open") -> open | F85: MEDIUM | G85: YES | H85: materials DB v2/v3
A86: gloeckler_2003_wcpec | D86: =HYPERLINK("https://doi.org/"&C86,"open") -> open | G86: — | H86: materials DB v2/v3
A87: song_2016_vacuum | C87: 10.1016/j.vacuum.2015.03.008 | D87: =HYPERLINK("https://doi.org/"&C87,"open") -> open | G87: — | H87: materials DB v2/v3
A88: kephart_2016_solmat | C88: 10.1016/j.solmat.2016.05.050 | D88: =HYPERLINK("https://doi.org/"&C88,"open") -> open | G88: — | H88: materials DB v2/v3
A89: zyoud_2021_crystals | C89: 10.3390/cryst11121454 | D89: =HYPERLINK("https://doi.org/"&C89,"open") -> open | F89: HIGH | G89: YES | H89: materials DB v2/v3

Sheet Physical_Constants
A1: Physical and model constants
A2: CODATA 2018 fundamental constants and the published model coefficients used verbatim in the engines.
A4: Symbol | B4: Value | C4: Unit | D4: Meaning | E4: Source
A5: q | B5: 1.6021766e-19 | C5: C | D5: Elementary charge | E5: CODATA 2018 (exact)
A6: k_B | B6: 1.380649e-23 | C6: J/K | D6: Boltzmann constant | E6: CODATA 2018 (exact)
A7: h | B7: 6.6260701e-34 | C7: J·s | D7: Planck constant | E7: CODATA 2018 (exact)
A8: c | B8: 299792458 | C8: m/s | D8: Speed of light | E8: CODATA 2018 (exact)
A9: V_T(300K) | B9: 0.025852 | C9: V | D9: Thermal voltage kT/q | E9: derived (=k_B·300/q)
A10: n_i,eff (Si, 300K) | B10: 9650000000 | C10: cm⁻³ | D10: Effective intrinsic density, c-Si | E10: Altermatt 2003, DOI 10.1063/1.1529297
A11: C_eeh (Auger) | B11: 2.5e-31 | C11: cm⁶/s | D11: e-e-h Auger coefficient | E11: Richter 2012, DOI 10.1103/PhysRevB.86.165202
A12: C_ehh (Auger) | B12: 8.5e-32 | C12: cm⁶/s | D12: e-h-h Auger coefficient | E12: Richter 2012
A13: C_Δn (Auger) | B13: 3e-29 | C13: cm⁶/s (Δn^0.92) | D13: Injection-dependent Auger term | E13: Richter 2012
A14: B_low (rad.) | B14: 4.73e-15 | C14: cm³/s | D14: Radiative coefficient, c-Si | E14: Richter 2012 param. set
A15: Si SJ limit | B15: 0.294 | C15: — | D15: Max single-junction c-Si efficiency (enforced bound) | E15: Niewelt 2022, DOI 10.1016/j.solmat.2021.111467
A16: AM1.5G P_in | B16: 100 | C16: mW/cm² | D16: Standard test condition irradiance | E16: ASTM G173-03

Sheet Materials_Perovskite
A1: Material parameter database — perovskite/CdTe stack materials
A2: Source: data/materials_database.json (per-parameter provenance in file). Eg [eV], chi [eV], eps [rel], Nc/Nv [cm⁻³], mu [cm²/Vs], doping [cm⁻³], alpha0 [cm⁻¹·eV^-1/2].
A4: Class | B4: Material | C4: Eg | D4: chi | E4: eps | F4: Nc | G4: Nv | H4: mu_e | I4: mu_h | J4: Doping | K4: Type | L4: alpha0 | M4: References (registry keys)
A5: Absorber | B5: MAPbI3 | C5: 1.55 | D5: 3.93 | E5: 6.5 | F5: 2.2e+18 | G5: 1.8e+19 | H5: 2 | I5: 2 | J5: 10000000000000 | K5: p | L5: 150000 | M5: b, r, i, v
A6: Absorber | B6: FAPbI3 | C6: 1.48 | D6: 4 | E6: 6.6 | F6: 2.2e+18 | G6: 1.8e+19 | H6: 2.7 | I6: 2.7 | J6: 10000000000000 | K6: p | L6: 140000 | M6: e, p, e, r
A7: Absorber | B7: CsPbI3 | C7: 1.694 | D7: 3.95 | E7: 6 | F7: 1.1e+20 | G7: 8.2e+20 | H7: 25 | I7: 25 | J7: 1e+15 | K7: p | L7: 120000 | M7: h, o, s, s
A8: Absorber | B8: Cs2SnI6 | C8: 1.48 | D8: 4.01 | E8: 10 | F8: 2.2e+18 | G8: 1.8e+19 | H8: 53 | I8: 0.03 | J8: 1.2e+16 | K8: p | L8: 120000 | M8: c, h, a, b
A9: Absorber | B9: MAPbBr3 | C9: 2.3 | D9: 3.38 | E9: 4 | F9: 2.2e+18 | G9: 1.8e+19 | H9: 1 | I9: 1 | J9: 10000000000000 | K9: p | L9: 50000 | M9: b, r, i, v
A10: Absorber | B10: MASnI3 | C10: 1.3 | D10: 4.17 | E10: 8.2 | F10: 1e+18 | G10: 1e+18 | H10: 1.6 | I10: 1.6 | J10: 3.2e+15 | K10: p | L10: 50000 | M10: w, a, n, g
A11: Absorber | B11: CsSnI3 | C11: 1.3 | D11: 3.6 | E11: 9.93 | F11: 1e+18 | G11: 1e+18 | H11: 1.5 | I11: 58 | J11: 1e+17 | K11: p | L11: 50000 | M11: c, h, u, n
A12: Absorber | B12: FASnI3 | C12: 1.41 | D12: 3.52 | E12: 8.2 | F12: 1e+18 | G12: 1e+18 | H12: 22 | I12: 22 | J12: 1e+17 | K12: p | L12: 50000 | M12: k, o, h, _
A13: Absorber | B13: FA0.83Cs0.17Pb_I0.6Br0.4_3 | C13: 1.68 | D13: 3.95 | E13: 6.5 | F13: 1e+19 | G13: 1e+19 | H13: 2 | I13: 2 | J13: 1e+15 | K13: p | L13: 100000 | M13: y, o, o, _
A14: Absorber | B14: CdTe | C14: 1.5 | D14: 3.9 | E14: 9.4 | F14: 8e+17 | G14: 1.8e+19 | H14: 320 | I14: 40 | J14: 200000000000000 | K14: p | L14: 300000 | M14: g, l, o, e
A15: ETL | B15: SnO2 | C15: 3.6 | D15: 4 | E15: 9 | F15: 2.2e+18 | G15: 1.8e+19 | H15: 100 | I15: 25 | J15: 1e+17 | K15: n | L15: 100000 | M15: h, o, s, s
A16: ETL | B16: TiO2 | C16: 3.2 | D16: 4 | E16: 9 | F16: 2.2e+18 | G16: 1.8e+19 | H16: 20 | I16: 10 | J16: 1e+17 | K16: n | L16: 100000 | M16: h, o, s, s
... A39: HTL | B39: CdTe-BSF | C39: 1.5 | D39: 3.9 | E39: 9.4 | F39: 8e+17 | G39: 1.8e+19 | H39: 320 | I39: 40 | J39: 1e+18 | K39: p | L39: 300000 | M39: g, l, o, e

Sheet Silicon_Presets
A1: Crystalline-silicon architecture presets vs certified record devices
A2: Model results computed live by physics/silicon.py at build time. Error and PASS columns are formulas. Reproduce: scripts/run_multi_tech_validation.py
A4: Preset | B4: W [µm] | C4: N_dop [cm⁻³] | D4: τ_SRH [ms] | E4: J0s [fA/cm²] | F4: Rs [Ω·cm²] | G4: Certified PCE % | H4: Model PCE % | I4: Model Voc [V] | J4: Model Jsc | K4: Model FF | L4: |Err| % | M4: Tol % | N4: PASS | O4: DOI | P4: Link
A5: SHJ-IBC (Kaneka 26.7%) | B5: 165 | C5: 3e+15 | D5: 15 | E5: 2.6 | F5: 0.32 | G5: 26.7 | H5: 26.771 | I5: 0.745 | J5: 43 | K5: 0.8357 | L5: =ABS(H5-G5)/G5 -> 0.002659176 | M5: 0.03 | N5: =IF(L5<=M5,"PASS","FAIL") -> PASS | O5: 10.1016/j.solmat.2017.06.024 | P5: =HYPERLINK("https://doi.org/"&O5,"open") -> open
A6: SHJ both-side (LONGi 26.81%) | B6: 130 | C6: 1.6e+15 | D6: 50 | E6: 1.1 | F6: 0.1 | G6: 26.81 | H6: 26.755 | I6: 0.7539 | J6: 41.8 | K6: 0.849 | L6: =ABS(H6-G6)/G6 -> 0.0020514733 | M6: 0.03 | N6: =IF(L6<=M6,"PASS","FAIL") -> PASS | O6: 10.1038/s41560-023-01255-2 | P6: =HYPERLINK("https://doi.org/"&O6,"open") -> open
A7: TOPCon back junction (Fraunhofer 26.0%) | B7: 200 | C7: 1e+16 | D7: 12 | E7: 4 | F7: 0.3 | G7: 26 | H7: 25.981 | I7: 0.7328 | J7: 42.46 | K7: 0.8349 | L7: =ABS(H7-G7)/G7 -> 0.00073076923 | M7: 0.03 | N7: =IF(L7<=M7,"PASS","FAIL") -> PASS | O7: 10.1038/s41560-021-00805-w | P7: =HYPERLINK("https://doi.org/"&O7,"open") -> open
A8: PERC industrial (~24%) | B8: 170 | C8: 9e+15 | D8: 1.2 | E8: 45 | F8: 0.45 | G8: 24.06 | H8: 23.601 | I8: 0.7023 | J8: 41.1 | K8: 0.8176 | L8: =ABS(H8-G8)/G8 -> 0.019077307 | M8: 0.05 | N8: =IF(L8<=M8,"PASS","FAIL") -> PASS | O8: 10.1002/pip.3371 | P8: =HYPERLINK("https://doi.org/"&O8,"open") -> open
A9: Al-BSF legacy (~20%) | B9: 180 | C9: 1.5e+16 | D9: 0.25 | E9: 350 | F9: 0.75 | G9: 20.1 | H9: 20.163 | I9: 0.6525 | J9: 38.8 | K9: 0.7964 | L9: =ABS(H9-G9)/G9 -> 0.0031343284 | M9: 0.06 | N9: =IF(L9<=M9,"PASS","FAIL") -> PASS | O9: 10.1002/pip.3371 | P9: =HYPERLINK("https://doi.org/"&O9,"open") -> open

Sheet Organic_Presets
A1: Organic BHJ blend presets vs certified record devices
A2: Model results live from physics/organic.py (calibrated optics). TMM cross-path PCE included where an n,k dataset exists.
A4: Blend preset | B4: Eg_opt [eV] | C4: E_loss [eV] | D4: EQE_max | E4: L [nm] | F4: n_id | G4: Rs [Ω·cm²] | H4: Certified PCE % | I4: Model PCE % | J4: TMM-optics PCE % | K4: Model Voc | L4: Model Jsc | M4: Model FF | N4: |Err| % | O4: Tol % | P4: PASS | Q4: DOI | R4: Link
A5: PM6:Y6 (Joule 2019, 15.7%) | B5: 1.33 | C5: 0.5 | D5: 0.769 | E5: 100 | F5: 1.52 | G5: 2.2 | H5: 15.7 | I5: 15.568 | J5: 14.88 | K5: 0.8291 | L5: 25.29 | M5: 0.7424 | N5: =ABS(I5-H5)/H5 -> 0.0084076433 | O5: 0.04 | P5: =IF(N5<=O5,"PASS","FAIL") -> PASS | Q5: 10.1016/j.joule.2019.01.004 | R5: =HYPERLINK("https://doi.org/"&Q5,"open") -> open
A6: PM6:L8-BO (Nat. Energy 2021, 18.3%) | B6: 1.4 | C6: 0.53 | D6: 0.854 | E6: 105 | F6: 1.24 | G6: 1 | H6: 18.32 | I6: 18.204 | J6: n/a (no n,k set) | K6: 0.8696 | L6: 25.81 | M6: 0.8112 | N6: =ABS(I6-H6)/H6 -> 0.0063318777 | O6: 0.04 | P6: =IF(N6<=O6,"PASS","FAIL") -> PASS | Q6: 10.1038/s41560-021-00820-x | R6: =HYPERLINK("https://doi.org/"&Q6,"open") -> open
A7: PBQx-TF:eC9-2Cl (Adv. Mater. 2021, 19.0%) | B7: 1.38 | C7: 0.501 | D7: 0.861 | E7: 110 | F7: 1.22 | G7: 0.9 | H7: 19 | I7: 19.195 | J7: n/a (no n,k set) | K7: 0.8787 | L7: 26.69 | M7: 0.8183 | N7: =ABS(I7-H7)/H7 -> 0.010263158 | O7: 0.04 | P7: =IF(N7<=O7,"PASS","FAIL") -> PASS | Q7: 10.1002/adma.202102420 | R7: =HYPERLINK("https://doi.org/"&Q7,"open") -> open
A8: PM6:L8-BO-C4 (Nat. Mater. 2025, 20.4%) | B8: 1.42 | C8: 0.526 | D8: 0.95 | E8: 110 | F8: 1.18 | G8: 0.8 | H8: 20.42 | I8: 20.672 | J8: n/a (no n,k set) | K8: 0.8938 | L8: 27.97 | M8: 0.827 | N8: =ABS(I8-H8)/H8 -> 0.012340842 | O8: 0.04 | P8: =IF(N8<=O8,"PASS","FAIL") -> PASS | Q8: 10.1038/s41563-024-02087-5 | R8: =HYPERLINK("https://doi.org/"&Q8,"open") -> open
A9: P3HT:PC61BM (legacy, ~4%) | B9: 1.85 | C9: 1.25 | D9: 0.643 | E9: 200 | F9: 1.6 | G9: 3 | H9: 4 | I9: 4.05 | J9: 4.065 | K9: 0.5968 | L9: 10.01 | M9: 0.6781 | N9: =ABS(I9-H9)/H9 -> 0.0125 | O9: 0.25 | P9: =IF(N9<=O9,"PASS","FAIL") -> PASS | Q9: 10.1103/PhysRevB.72.085205 | R9: =HYPERLINK("https://doi.org/"&Q9,"open") -> open

Sheet Tandem_Grades
A1: Perovskite/Si tandem grade presets vs the certified record lineage
A2: Grades = documented interface-quality eras (four scalars each, ranges in VALIDATION_MULTI_TECH.md). Model live from physics/tandem.py; 2023 grade optimizes top thickness in [400,1100] nm.
A4: Grade | B4: N_t,top [cm⁻³] | C4: R_int | D4: Parasitic | E4: Rs,int [Ω·cm²] | F4: d_top [nm] | G4: Certified PCE % | H4: Model PCE % | I4: Model Voc [V] | J4: Model Jsc | K4: Model FF | L4: |Err| % | M4: Tol % | N4: PASS | O4: DOI | P4: Link
A5: 2020 (alashouri_2020) | B5: 200000000000000 | C5: 0.07 | D5: 0.05 | E5: 4.5 | F5: 650 | G5: 29.15 | H5: 29.155 | I5: 1.9215 | J5: 17.9 | K5: 0.8474 | L5: =ABS(H5-G5)/G5 -> 0.00017152659 | M5: 0.05 | N5: =IF(L5<=M5,"PASS","FAIL") -> PASS | O5: 10.1126/science.abd4016 | P5: =HYPERLINK("https://doi.org/"&O5,"open") -> open
A6: 2023 (chin_mariotti_2023) | B6: 100000000000000 | C6: 0.05 | D6: 0.035 | E6: 2.5 | F6: 700 | G6: 31.875 | H6: 31.751 | I6: 1.9401 | J6: 19.01 | K6: 0.8608 | L6: =ABS(H6-G6)/G6 -> 0.0038901961 | M6: 0.05 | N6: =IF(L6<=M6,"PASS","FAIL") -> PASS | O6: 10.1126/science.adg0091 | P6: =HYPERLINK("https://doi.org/"&O6,"open") -> open
A7: 2025 (jia_2025) | B7: 30000000000000 | C7: 0.03 | D7: 0.02 | E7: 1.5 | F7: 800 | G7: 34.58 | H7: 34.163 | I7: 1.9718 | J7: 20.02 | K7: 0.8656 | L7: =ABS(H7-G7)/G7 -> 0.012058994 | M7: 0.05 | N7: =IF(L7<=M7,"PASS","FAIL") -> PASS | O7: 10.1038/s41586-025-09333-z | P7: =HYPERLINK("https://doi.org/"&O7,"open") -> open
A9: Note: 2023 target is the mid-point of the certified 31.25–32.5% band (Chin 2023 / Mariotti 2023). Disclosed 2020-grade Jsc/FF trade-off documented in VALIDATION_MULTI_TECH.md.

Sheet Benchmarks_Experimental
A1: Experimental validation — 14 certified fabricated devices
A2: Source artifact: artifacts/validation_multi_tech.json (regenerate: python scripts/run_multi_tech_validation.py). Error and PASS columns are live formulas.
A4: ID | B4: Technology | C4: Reference key | D4: Certified PCE % | E4: Model PCE % | F4: Model Voc [V] | G4: Model Jsc | H4: |Err| % | I4: Tolerance % | J4: PASS | K4: DOI | L4: Link
A5: yoshikawa_2017_shj_ibc | B5: Silicon | C5: yoshikawa_2017_solmat | D5: 26.7 | E5: 26.7706 | F5: 0.745 | G5: 42.9954 | H5: =ABS(E5-D5)/D5 -> 0.0026441948 | I5: 0.03 | J5: =IF(H5<=I5,"PASS","FAIL") -> PASS | K5: 10.1016/j.solmat.2017.06.024 | L5: =HYPERLINK("https://doi.org/"&K5,"open") -> open
A6: lin_2023_shj | B6: Silicon | C6: lin_2023_natenergy | D6: 26.81 | E6: 26.7548 | F6: 0.7539 | G6: 41.8022 | H6: =ABS(E6-D6)/D6 -> 0.0020589332 | I6: 0.03 | J6: =IF(H6<=I6,"PASS","FAIL") -> PASS | K6: 10.1038/s41560-023-01255-2 | L6: =HYPERLINK("https://doi.org/"&K6,"open") -> open
A7: richter_2021_topcon | B7: Silicon | C7: richter_2021_natenergy | D7: 26 | E7: 25.9811 | F7: 0.7328 | G7: 42.4621 | H7: =ABS(E7-D7)/D7 -> 0.00072692308 | I7: 0.03 | J7: =IF(H7<=I7,"PASS","FAIL") -> PASS | K7: 10.1038/s41560-021-00805-w | L7: =HYPERLINK("https://doi.org/"&K7,"open") -> open
A8: perc_industrial | B8: Silicon | C8: green_2021_tables57 | D8: 24.06 | E8: 23.6008 | F8: 0.7023 | G8: 41.1026 | H8: =ABS(E8-D8)/D8 -> 0.019085619 | I8: 0.05 | J8: =IF(H8<=I8,"PASS","FAIL") -> PASS | K8: 10.1002/pip.3371 | L8: =HYPERLINK("https://doi.org/"&K8,"open") -> open
A9: albsf_legacy | B9: Silicon | C9: green_2021_tables57 | D9: 20.1 | E9: 20.1627 | F9: 0.6525 | G9: 38.8011 | H9: =ABS(E9-D9)/D9 -> 0.003119403 | I9: 0.06 | J9: =IF(H9<=I9,"PASS","FAIL") -> PASS | K9: 10.1002/pip.3371 | L9: =HYPERLINK("https://doi.org/"&K9,"open") -> open
A10: yuan_2019_pm6y6 | B10: Organic | C10: yuan_2019_joule | D10: 15.7 | E10: 15.568 | F10: 0.8291 | G10: 25.2916 | H10: =ABS(E10-D10)/D10 -> 0.0084076433 | I10: 0.04 | J10: =IF(H10<=I10,"PASS","FAIL") -> PASS | K10: 10.1016/j.joule.2019.01.004 | L10: =HYPERLINK("https://doi.org/"&K10,"open") -> open
A11: yuan_2019_pm6y6_300nm | B11: Organic | C11: yuan_2019_joule | D11: 13.6 | E11: 13.4237 | F11: 0.8289 | G11: 21.6439 | H11: =ABS(E11-D11)/D11 -> 0.012963235 | I11: 0.2 | J11: =IF(H11<=I11,"PASS","FAIL") -> PASS | K11: 10.1016/j.joule.2019.01.004 | L11: =HYPERLINK("https://doi.org/"&K11,"open") -> open
A12: li_2021_l8bo | B12: Organic | C12: li_2021_natenergy | D12: 18.32 | E12: 18.204 | F12: 0.8696 | G12: 25.8052 | H12: =ABS(E12-D12)/D12 -> 0.0063318777 | I12: 0.04 | J12: =IF(H12<=I12,"PASS","FAIL") -> PASS | K12: 10.1038/s41560-021-00820-x | L12: =HYPERLINK("https://doi.org/"&K12,"open") -> open
A13: cui_2021_19pct | B13: Organic | C13: cui_2021_advmater | D13: 19 | E13: 19.1946 | F13: 0.8787 | G13: 26.6947 | H13: =ABS(E13-D13)/D13 -> 0.010242105 | I13: 0.04 | J13: =IF(H13<=I13,"PASS","FAIL") -> PASS | K13: 10.1002/adma.202102420 | L13: =HYPERLINK("https://doi.org/"&K13,"open") -> open
A14: li_2025_204pct | B14: Organic | C14: li_2025_natmater | D14: 20.42 | E14: 20.6719 | F14: 0.8938 | G14: 27.9671 | H14: =ABS(E14-D14)/D14 -> 0.012335945 | I14: 0.04 | J14: =IF(H14<=I14,"PASS","FAIL") -> PASS | K14: 10.1038/s41563-024-02087-5 | L14: =HYPERLINK("https://doi.org/"&K14,"open") -> open
A15: p3ht_pcbm | B15: Organic | C15: koster_2005_prb | D15: 4 | E15: 4.0497 | F15: 0.5968 | G15: 10.0073 | H15: =ABS(E15-D15)/D15 -> 0.012425 | I15: 0.25 | J15: =IF(H15<=I15,"PASS","FAIL") -> PASS | K15: 10.1103/PhysRevB.72.085205 | L15: =HYPERLINK("https://doi.org/"&K15,"open") -> open
A16: alashouri_2020 | B16: Tandem | C16: alashouri_2020_science | D16: 29.15 | E16: 29.1555 | F16: 1.9215 | G16: 17.9045 | H16: =ABS(E16-D16)/D16 -> 0.00018867925 | I16: 0.05 | J16: =IF(H16<=I16,"PASS","FAIL") -> PASS | K16: 10.1126/science.abd4016 | L16: =HYPERLINK("https://doi.org/"&K16,"open") -> open
... A18: jia_2025 | B18: Tandem | C18: jia_2025_nature | D18: 34.58 | E18: 34.1628 | F18: 1.9718 | G18: 20.016 | H18: =ABS(E18-D18)/D18 -> 0.012064777 | I18: 0.05 | J18: =IF(H18<=I18,"PASS","FAIL") -> PASS | K18: 10.1038/s41586-025-09333-z | L18: =HYPERLINK("https://doi.org/"&K18,"open") -> open
A20: Suite summary | D20: Mean |err|: | E20: =AVERAGE(H5:H18) -> 0.0076051417 | F20: Max |err|: | G20: =MAX(H5:H18) -> 0.019085619 | I20: Pass: | J20: =COUNTIF(J5:J18,"PASS")&"/14" -> 14/14

Sheet CrossTool_Checks
A1: Cross-tool validation — SCAPS-1D, Lumerical-class TMM, internal redundancy
A2: Source artifact: artifacts/validation_cross_tool.json (regenerate: python scripts/run_cross_tool_validation.py).
A4: ID | B4: Check | C4: Result detail | D4: Family | E4: PASS
A5: C1a | B5: energy conservation R+T+ΣA=1 | C5: max err 9.73e-05 | D5: Lumerical-class optics (TMM) | E5: PASS
A6: C1b | B6: Fresnel limit glass/air | C6: R=0.04257999 vs analytic 0.04257999 | D6: Lumerical-class optics (TMM) | E6: PASS
A7: C1c | B7: P3HT:PCBM Jsc(L) interference vs published TMM | C7: maxima [80.0, 215.0] nm at [8.38, 10.11] mA/cm², min 130.0 nm (Sievers 2006 / Kotlarski 2008 / Monestier 2007) | D7: Lumerical-class optics (TMM) | E7: PASS
A8: C1d | B8: NFA blend first optical optimum near ~100 nm | C8: first-region optimum 90 nm (Im 2023) | D8: Lumerical-class optics (TMM) | E8: PASS
A9: C1e | B9: PM6:Y6 TMM Jsc vs certified device (Yuan 2019) | C9: 24.01 vs 25.3 mA/cm² (5.1% dev; published TMM band ~16%, Rosa 2021) | D9: Lumerical-class optics (TMM) | E9: PASS
A10: C1f | B10: independent-path PCE: TMM optics vs calibrated optics | C10: 14.88% vs 15.57% (4.4% dev) | D10: Lumerical-class optics (TMM) | E10: PASS
A11: C2a | B11: .def export → re-import round trip | C11: layer count + Eg + χ parameter-exact | D11: SCAPS-1D interoperability | E11: PASS
A12: C2b | B12: published-SCAPS numerical cross-check (v3 suite) | C12: published-SCAPS suite: 10 devices, mean PCE error 0.7%, worst 2.0% (v3 artifact re-asserted) | D12: SCAPS-1D interoperability | E12: PASS
A13: C3a | B13: silicon: Richter-2012 vs Niewelt-2022 intrinsic models | C13: 26.77% vs 26.92% (0.56% dev) | D13: Internal redundancy | E13: PASS

Sheet SCAPS_Suite
A1: Published-SCAPS replication suite — 10 devices
A2: Source artifact: artifacts/benchmark_results.json (v3 suite, re-asserted by the cross-tool script). Published SCAPS values from the cited papers vs this tool's drift-diffusion outputs.
A4: ID | B4: Stack | C4: Absorber | D4: SCAPS PCE % | E4: Our PCE % | F4: SCAPS Voc | G4: Our Voc | H4: SCAPS Jsc | I4: Our Jsc | J4: SCAPS FF | K4: Our FF | L4: |PCE err| % | M4: DOI | N4: Link | O4: Verified
A5: D1 | B5: ITO / PCBM / CsPbI3 / CBTS / Au | C5: CsPbI3 | D5: 16.71 | E5: 16.67 | F5: 0.994 | G5: 0.98 | H5: 19.77 | I5: 20.71 | J5: 0.8504 | K5: 0.8211 | L5: =ABS(E5-D5)/D5 -> 0.0023937762 | M5: 10.1021/acsomega.2c05912 | N5: =HYPERLINK("https://doi.org/"&M5,"open") -> open | O5: YES
A6: D2 | B6: ITO / TiO2 / CsPbI3 / CBTS / Au | C6: CsPbI3 | D6: 17.9 | E6: 17.85 | F6: 0.997 | G6: 1.105 | H6: 21.07 | I6: 20.61 | J6: 0.8521 | K6: 0.784 | L6: =ABS(E6-D6)/D6 -> 0.0027932961 | M6: 10.1021/acsomega.2c05912 | N6: =HYPERLINK("https://doi.org/"&M6,"open") -> open | O6: YES
A7: D3 | B7: ITO / ZnO / CsPbI3 / CBTS / Au | C7: CsPbI3 | D7: 17.86 | E7: 17.86 | F7: 0.997 | G7: 1.163 | H7: 21.07 | I7: 20.67 | J7: 0.8503 | K7: 0.7429 | L7: =ABS(E7-D7)/D7 -> 0 | M7: 10.1021/acsomega.2c05912 | N7: =HYPERLINK("https://doi.org/"&M7,"open") -> open | O7: YES
A8: D4 | B8: ITO / C60 / CsPbI3 / CBTS / Au | C8: CsPbI3 | D8: 14.47 | E8: 14.32 | F8: 0.989 | G8: 0.98 | H8: 17.25 | I8: 20.36 | J8: 0.848 | K8: 0.7172 | L8: =ABS(E8-D8)/D8 -> 0.010366275 | M8: 10.1021/acsomega.2c05912 | N8: =HYPERLINK("https://doi.org/"&M8,"open") -> open | O8: YES
A9: D5 | B9: ITO / IGZO / CsPbI3 / CBTS / Au | C9: CsPbI3 | D9: 17.76 | E9: 17.77 | F9: 0.995 | G9: 1.115 | H9: 20.98 | I9: 20.64 | J9: 0.8513 | K9: 0.7722 | L9: =ABS(E9-D9)/D9 -> 0.00056306306 | M9: 10.1021/acsomega.2c05912 | N9: =HYPERLINK("https://doi.org/"&M9,"open") -> open | O9: YES
A10: D6 | B10: ITO / WS2 / CsPbI3 / CBTS / Au | C10: CsPbI3 | D10: 17.82 | E10: 18.05 | F10: 0.997 | G10: 1.118 | H10: 20.98 | I10: 20.6 | J10: 0.8522 | K10: 0.784 | L10: =ABS(E10-D10)/D10 -> 0.012906846 | M10: 10.1021/acsomega.2c05912 | N10: =HYPERLINK("https://doi.org/"&M10,"open") -> open | O10: YES
A11: D7 | B11: ITO / CuI / Cs2SnI6 / ZnO / AZO / Ag | C11: Cs2SnI6 | D11: 14.65 | E11: 14.75 | F11: 0.873 | G11: 0.999 | H11: 22.8 | I11: 22.62 | J11: 0.736 | K11: 0.6524 | L11: =ABS(E11-D11)/D11 -> 0.0068259386 | M11: 10.1007/s11664-023-10235-x | N11: =HYPERLINK("https://doi.org/"&M11,"open") -> open | O11: YES
A12: D8 | B12: ITO / Cu2O / CsPbI3 / TiO2 / Au | C12: CsPbI3 | D12: 17.64 | E12: 18 | F12: 1 | G12: 1.145 | H12: 21.05 | I12: 20.7 | J12: 0.8402 | K12: 0.7597 | L12: =ABS(E12-D12)/D12 -> 0.020408163 | M12: 10.1021/acsomega.2c05912 | N12: =HYPERLINK("https://doi.org/"&M12,"open") -> open | O12: YES
A13: D9 | B13: ITO / CuSCN / CsPbI3 / TiO2 / Au | C13: CsPbI3 | D13: 17.81 | E13: 17.84 | F13: 0.99 | G13: 1.172 | H13: 21.05 | I13: 20.68 | J13: 0.8529 | K13: 0.7357 | L13: =ABS(E13-D13)/D13 -> 0.0016844469 | M13: 10.1021/acsomega.2c05912 | N13: =HYPERLINK("https://doi.org/"&M13,"open") -> open | O13: YES
A14: D10 | B14: ITO / Spiro-OMeTAD / CsPbI3 / TiO2 / Au | C14: CsPbI3 | D14: 17.18 | E14: 17.02 | F14: 0.99 | G14: 1.2 | H14: 21.05 | I14: 20.87 | J14: 0.821 | K14: 0.6797 | L14: =ABS(E14-D14)/D14 -> 0.0093131548 | M14: 10.1021/acsomega.2c05912 | N14: =HYPERLINK("https://doi.org/"&M14,"open") -> open | O14: YES
A16: Suite summary | K16: Mean: | L16: =AVERAGE(L5:L14) -> 0.006725496

Sheet Tutorial_Assertions
A1: Hand-solved mathematical verification — 22 executable assertions
A2: Source: live run of scripts/run_tutorial_examples.py at build time; full derivations in docs/TUTORIAL.md.
A4: Assertion ID | B4: Statement | C4: Detail (hand vs engine) | D4: PASS
A5: 1.1 | B5: photocurrent ceiling | C5: q*Phi(<=1200nm) = 46.41 mA/cm² (tutorial 46.41); engine Jsc 43.00 = 92.7% utilization | D5: PASS
A6: 1.2 | B6: open-circuit balance closes | C6: (R_intr+R_SRH+R_surf)/G - 1 = 1.2e-14 (1.196e+19+1.070e+18+3.230e+18 vs G=1.626e+19) | D6: PASS
A7: 1.3 | B7: hand Voc = engine Voc | C7: hand 0.7451 V vs engine 0.7451 V | D7: PASS
A8: 1.4 | B8: Green-1981 FF | C8: FF0=0.8529, rs=0.0185 -> hand 0.8356 vs engine 0.8357 | D8: PASS
A9: 1.5 | B9: PCE assembles to certified device | C9: 0.7450 x 43.00 x 0.8357 = 26.77% (certified 26.7%, Yoshikawa 2017) | D9: PASS
A10: 2.1 | B10: Voc = (Eg - E_loss)/q | C10: 1.33 - 0.50 = 0.830 V vs engine 0.829 V | D10: PASS
A11: 2.2 | B11: spectral window integral | C11: q∫Phi(350-932nm) = 34.90; xEQE(0.769) = 26.84; roll-off -> engine 25.29 (certified 25.3) | D11: PASS
A12: 2.3 | B12: diode J0 consistency | C12: hand 1.738e-08 vs engine 1.700e-08 mA/cm² | D12: PASS
A13: 2.4 | B13: PCE vs certified device | C13: 15.57% vs 15.7% (Yuan 2019) | D13: PASS
A14: 2.5 | B14: independent TMM optics path | C14: TMM 14.88% vs calibrated 15.57% (4.4% dev; Rosa-2021 band ~16%) | D14: PASS
A15: 3.1 | B15: Tauc absorption at 600 nm | C15: alpha = 5.216e+04 cm⁻¹, A(500 nm film) = 0.926 | D15: PASS
... A26: 6.2 | B26: analytic depletion anchor | C26: W_D = 1662 nm >> 500 nm -> fully depleted absorber, uniform field ~ V_bi/d = 20 kV/cm (PINN field check) | D26: PASS

Sheet TMM_nk_Data
A1: Complex refractive-index database of the transfer-matrix solver
A2: Source: physics/tmm.py (_NK). n interpolated linearly, k log-linearly between nodes. Organic-blend k carries ±5–10% ellipsometry batch spread (Kerremans 2020).
A4: Material | B4: λ [nm] | C4: n | D4: k | E4: Source
A5: glass | B5: 300 | C5: 1.52 | D5: 0 | E5: standard (BK7-class, dispersion negligible for PV)
B6: 1200 | C6: 1.52 | D6: 0
A7: ITO | B7: 350 | C7: 2.1 | D7: 0.06 | E7: Burkhard 2010 suppl. + refs, DOI 10.1002/adma.201000883
B8: 400 | C8: 2.05 | D8: 0.03
B9: 500 | C9: 1.95 | D9: 0.01
B10: 600 | C10: 1.85 | D10: 0.008
B11: 700 | C11: 1.78 | D11: 0.01
B12: 800 | C12: 1.72 | D12: 0.02
B13: 900 | C13: 1.65 | D13: 0.03
B14: 1000 | C14: 1.6 | D14: 0.05
B15: 1100 | C15: 1.55 | D15: 0.07
A16: PEDOT:PSS | B16: 350 | C16: 1.58 | D16: 0.012 | E16: Burkhard 2010 suppl.
B17: 500 | C17: 1.52 | D17: 0.008
B18: 700 | C18: 1.48 | D18: 0.015
B19: 1000 | C19: 1.42 | D19: 0.04
B20: 1100 | C20: 1.41 | D20: 0.05
A21: ZnO | B21: 350 | C21: 2.15 | D21: 0.08 | E21: standard device-modeling values
B22: 380 | C22: 2.05 | D22: 0.02
B23: 400 | C23: 1.95 | D23: 0.005
B24: 500 | C24: 1.92 | D24: 0.001
B25: 700 | C25: 1.88 | D25: 0.0005
B26: 1100 | C26: 1.85 | D26: 0.0003
A27: P3HT:PCBM | B27: 350 | C27: 1.7 | D27: 0.08 | E27: Monestier 2007, DOI 10.1016/j.solmat.2006.10.019; Burkhard 2010
B28: 400 | C28: 1.72 | D28: 0.12
B29: 450 | C29: 1.8 | D29: 0.22
B30: 480 | C30: 1.9 | D30: 0.28
B31: 500 | C31: 1.95 | D31: 0.31
B32: 520 | C32: 2 | D32: 0.33
B33: 550 | C33: 2.08 | D33: 0.3
B34: 580 | C34: 2.12 | D34: 0.25
B35: 600 | C35: 2.12 | D35: 0.17
B36: 620 | C36: 2.05 | D36: 0.1
B37: 650 | C37: 1.98 | D37: 0.035
B38: 700 | C38: 1.9 | D38: 0.005
B39: 800 | C39: 1.85 | D39: 0.001
... B41: 1100 | C41: 1.82 | D41: 0.0001
A42: PM6:Y6 | B42: 350 | C42: 1.65 | D42: 0.17 | E42: Kerremans 2020, DOI 10.1002/adom.202000319 (adjusted within batch spread)
...

Sheet JV_Curves
A1: Live simulated J-V data — all four technologies
A2: Generated by the engines at build time from the shipped presets; the chart below plots the four curves.
A4: V [Perovskite MAPbI3 (19.1%)] | B4: J [Perovskite MAPbI3 (19.1%)] | C4: V [Silicon SHJ-IBC (26.8%)] | D4: J [Silicon SHJ-IBC (26.8%)] | E4: V [Organic PM6:Y6 (15.6%)] | F4: J [Organic PM6:Y6 (15.6%)] | G4: V [Tandem pk/Si 2T (29.2%)] | H4: J [Tandem pk/Si 2T (29.2%)]
A5: 0 | B5: 21.47 | C5: 0 | D5: 42.995 | E5: 0 | F5: 25.292 | G5: 0 | H5: 0
A6: 0.01 | B6: 21.47 | C6: 0.0066 | D6: 42.995 | E6: 0.0075 | F6: 25.286 | G6: 0.0161 | H6: 0
A7: 0.0201 | B7: 21.47 | C7: 0.0131 | D7: 42.995 | E7: 0.0151 | F7: 25.281 | G7: 0.0323 | H7: 0
A8: 0.0301 | B8: 21.47 | C8: 0.0197 | D8: 42.995 | E8: 0.0226 | F8: 25.275 | G8: 0.0484 | H8: 0
A9: 0.0401 | B9: 21.47 | C9: 0.0263 | D9: 42.995 | E9: 0.0301 | F9: 25.27 | G9: 0.0646 | H9: 0
A10: 0.0502 | B10: 21.47 | C10: 0.0329 | D10: 42.995 | E10: 0.0377 | F10: 25.265 | G10: 0.0807 | H10: 0
A11: 0.0602 | B11: 21.47 | C11: 0.0394 | D11: 42.995 | E11: 0.0452 | F11: 25.259 | G11: 0.0969 | H11: 0
A12: 0.0702 | B12: 21.47 | C12: 0.046 | D12: 42.995 | E12: 0.0527 | F12: 25.254 | G12: 0.113 | H12: 0
A13: 0.0802 | B13: 21.47 | C13: 0.0526 | D13: 42.995 | E13: 0.0603 | F13: 25.249 | G13: 0.1292 | H13: 0
A14: 0.0903 | B14: 21.47 | C14: 0.0592 | D14: 42.995 | E14: 0.0678 | F14: 25.243 | G14: 0.1453 | H14: 0
A15: 0.1003 | B15: 21.47 | C15: 0.0657 | D15: 42.995 | E15: 0.0753 | F15: 25.238 | G15: 0.1615 | H15: 0
A16: 0.1103 | B16: 21.47 | C16: 0.0723 | D16: 42.995 | E16: 0.0829 | F16: 25.232 | G16: 0.1776 | H16: 0
... A124: 1.1936 | B124: -106.629 | C124: 0.7823 | D124: -52.203 | E124: 0.8964 | F124: -20.021 | G124: 1.9215 | H124: 17.896
